2025-08-26 14:53:28,352 - INFO - üöÄ Starting automated workflow monitoring and fixing...
2025-08-26 14:53:28,353 - INFO - üìä Iteration 1/3
2025-08-26 14:53:29,216 - INFO - ‚ùå Found 2 failed workflow(s)
2025-08-26 14:53:29,216 - INFO - üîç Analyzing failed workflow: SmartCloudOps AI - CI/CD Pipeline (ID: 17233688587)
2025-08-26 14:53:29,699 - INFO - üîç Analyzing failed job: Test Application (ubuntu-latest, 3.11)
2025-08-26 14:53:30,040 - ERROR - Error fetching logs for job 48893455183: 404 Client Error: Not Found for url: https://api.github.com/repos/Dileepreddy93/smartcloudops-ai/actions/runs/17233688587/jobs/48893455183/logs
2025-08-26 14:53:30,040 - INFO - üîç Analyzing failed workflow: Code Quality & Security (ID: 17233688584)
2025-08-26 14:53:30,541 - INFO - üîç Analyzing failed job: Code Quality & Security
2025-08-26 14:53:30,952 - ERROR - Error fetching logs for job 48893455130: 404 Client Error: Not Found for url: https://api.github.com/repos/Dileepreddy93/smartcloudops-ai/actions/runs/17233688584/jobs/48893455130/logs
2025-08-26 14:53:30,952 - INFO - ‚ÑπÔ∏è No automatic fixes available - manual intervention needed
2025-08-26 14:53:30,953 - INFO - üìä Generating monitoring report...
2025-08-26 14:53:30,953 - INFO - üìä Report saved to workflow_monitor_report.json
2025-08-27 16:03:03,745 - INFO - üîß Fixing dependency issues...
2025-08-27 16:03:03,747 - INFO - Updating Python dependencies...
2025-08-27 16:03:26,359 - ERROR - ‚ùå Failed to fix dependency issues: Command '['pip', 'install', '-r', 'app/requirements.txt']' returned non-zero exit status 1.
2025-08-27 16:03:26,359 - INFO - üß™ Fixing test issues...
2025-08-27 16:03:27,757 - WARNING - Test command failed: python -m pytest tests/phase_2/ -v --tb=short
2025-08-27 16:03:27,757 - WARNING - Output: ============================= test session starts ==============================
platform linux -- Python 3.12.3, pytest-8.4.1, pluggy-1.6.0 -- /home/dileep-reddy/smartcloudops-ai/workflow_monitor_env/bin/python
cachedir: .pytest_cache
rootdir: /home/dileep-reddy/smartcloudops-ai
configfile: pytest.ini
plugins: cov-6.2.1, anyio-4.10.0, flask-1.3.0, mock-3.14.1
collecting ... collected 0 items / 1 error

==================================== ERRORS ====================================
____________ ERROR collecting tests/phase_2/test_api_blueprints.py _____________
ImportError while importing test module '/home/dileep-reddy/smartcloudops-ai/tests/phase_2/test_api_blueprints.py'.
Hint: make sure your test modules/packages have valid Python names.
Traceback:
/usr/lib/python3.12/importlib/__init__.py:90: in import_module
    return _bootstrap._gcd_import(name[level:], package, level)
           ^^^^^^^^^^^^^^^^^^^^^^^^^^^^^^^^^^^^^^^^^^^^^^^^^^^^
tests/phase_2/test_api_blueprints.py:8: in <module>
    from app.api.v1 import health, chatops, logs, ml
app/api/v1/health.py:5: in <module>
    from app.core.ml_engine.secure_inference import SecureMLInferenceEngine
app/core/ml_engine/secure_inference.py:19: in <module>
    import numpy as np
E   ModuleNotFoundError: No module named 'numpy'
=========================== short test summary info ============================
ERROR tests/phase_2/test_api_blueprints.py
!!!!!!!!!!!!!!!!!!!!!!!!!! stopping after 1 failures !!!!!!!!!!!!!!!!!!!!!!!!!!!
=============================== 1 error in 0.22s ===============================

2025-08-27 16:03:27,757 - WARNING - Error: 
2025-08-27 16:03:28,315 - WARNING - Test command failed: python -m pytest tests/phase_3/ -v --tb=short
2025-08-27 16:03:28,315 - WARNING - Output: ============================= test session starts ==============================
platform linux -- Python 3.12.3, pytest-8.4.1, pluggy-1.6.0 -- /home/dileep-reddy/smartcloudops-ai/workflow_monitor_env/bin/python
cachedir: .pytest_cache
rootdir: /home/dileep-reddy/smartcloudops-ai
configfile: pytest.ini
plugins: cov-6.2.1, anyio-4.10.0, flask-1.3.0, mock-3.14.1
collecting ... collected 0 items / 1 error

==================================== ERRORS ====================================
_____________ ERROR collecting tests/phase_3/test_ml_inference.py ______________
ImportError while importing test module '/home/dileep-reddy/smartcloudops-ai/tests/phase_3/test_ml_inference.py'.
Hint: make sure your test modules/packages have valid Python names.
Traceback:
/usr/lib/python3.12/importlib/__init__.py:90: in import_module
    return _bootstrap._gcd_import(name[level:], package, level)
           ^^^^^^^^^^^^^^^^^^^^^^^^^^^^^^^^^^^^^^^^^^^^^^^^^^^^
tests/phase_3/test_ml_inference.py:9: in <module>
    from app.core.ml_engine.secure_inference import (
app/core/ml_engine/secure_inference.py:19: in <module>
    import numpy as np
E   ModuleNotFoundError: No module named 'numpy'
=========================== short test summary info ============================
ERROR tests/phase_3/test_ml_inference.py
!!!!!!!!!!!!!!!!!!!!!!!!!! stopping after 1 failures !!!!!!!!!!!!!!!!!!!!!!!!!!!
=============================== 1 error in 0.10s ===============================

2025-08-27 16:03:28,315 - WARNING - Error: 
2025-08-27 16:03:30,314 - INFO - ‚úÖ Test issues addressed
2025-08-27 16:03:30,315 - INFO - üé® Fixing linting issues...
2025-08-27 16:03:32,536 - WARNING - Linting command failed: flake8 app/ --max-line-length 127 --ignore E501,W503
2025-08-27 16:03:37,089 - INFO - ‚úÖ Linting issues fixed
2025-08-27 16:03:37,091 - INFO - üîí Fixing security issues...
2025-08-27 16:03:50,498 - INFO - ‚úÖ Security issues addressed
